<sdf version='1.7'>
  <world name='umd'>
    <physics name='default_physics' default='1' type='ode'>
      <max_step_size>0.002</max_step_size>
      <real_time_factor>1</real_time_factor>
      <real_time_update_rate>500</real_time_update_rate>
    </physics>
    <scene>
      <ambient>0.5 0.5 0.5 1</ambient>
      <sky>
        <clouds>
          <speed>12</speed>
        </clouds>
      </sky>
      <shadows>1</shadows>
      <fog>
        <color>0.1 0.2 0.3 1</color>
        <type>linear</type>
        <density>0.1</density>
        <start>1</start>
        <end>40</end>
      </fog>
      <background>0.7 0.7 0.7 1</background>
    </scene>
    <spherical_coordinates>
      <latitude_deg>56.719</latitude_deg>
      <longitude_deg>3.51562</longitude_deg>
      <surface_model>EARTH_WGS84</surface_model>
      <elevation>0</elevation>
      <heading_deg>0</heading_deg>
    </spherical_coordinates>
    <light name='sun' type='directional'>
      <pose>-50 -50 150 0 -0 0</pose>
      <diffuse>0.5 0.5 0.5 1</diffuse>
      <specular>0.1 0.1 0.1 1</specular>
      <direction>0.3 0.3 -1</direction>
      <cast_shadows>0</cast_shadows>
      <attenuation>
        <range>10</range>
      </attenuation>
      <spot>
        <inner_angle>0</inner_angle>
        <outer_angle>0</outer_angle>
        <falloff>0</falloff>
      </spot>
    </light>
    <light name='sun_diffuse' type='directional'>
      <pose>-50 0 -150 0 -0 0</pose>
      <diffuse>0.6 0.6 0.6 1</diffuse>
      <specular>0 0 0 1</specular>
      <direction>-0.3 -0.3 -1</direction>
      <cast_shadows>0</cast_shadows>
      <attenuation>
        <range>10</range>
      </attenuation>
      <spot>
        <inner_angle>0</inner_angle>
        <outer_angle>0</outer_angle>
        <falloff>0</falloff>
      </spot>
    </light>
    <model name='umd'>
      <static>1</static>
      <link name='base_link'>
        <collision name='collision'>
          <pose>0 0 0 0 -0 0</pose>
          <geometry>
            <mesh>
              <uri>model://umd/meshes/umd.dae</uri>
            </mesh>
          </geometry>
          <max_contacts>10</max_contacts>
          <surface>
            <contact>
              <ode/>
            </contact>
            <bounce/>
            <friction>
              <torsional>
                <ode/>
              </torsional>
              <ode/>
            </friction>
          </surface>
        </collision>
        <visual name='visual'>
          <cast_shadows>1</cast_shadows>
          <pose>0 0 0 0 -0 0</pose>
          <geometry>
            <mesh>
              <uri>model://umd/meshes/umd.dae</uri>
            </mesh>
          </geometry>
        </visual>
        <self_collide>0</self_collide>
        <enable_wind>0</enable_wind>
        <kinematic>0</kinematic>
      </link>
      <pose>0 0 0 0 -0 0</pose>
    </model>
    <model name='water'>
      <static>1</static>
      <link name='water_link'>
        <visual name='surface'>
          <pose>0 0 0 3.14 -0 0</pose>
          <cast_shadows>0</cast_shadows>
          <geometry>
            <mesh>
              <uri>file://Media/models/sea_surface_1000m_x_1000m.dae</uri>
            </mesh>
          </geometry>
          <material>
            <script>
              <uri>file://Media/materials/scripts/waves.material</uri>
              <name>UUVSimulator/SimpleWaves</name>
            </script>
          </material>
        </visual>
        <self_collide>0</self_collide>
        <enable_wind>0</enable_wind>
        <kinematic>0</kinematic>
      </link>
      <pose>0 0 0 0 -0 0</pose>
    </model>
    <model name='gate'>
      <static>1</static>
      <link name='base_link'>
        <collision name='collision'>
          <pose>0 0 0 0 -0 0</pose>
          <geometry>
            <mesh>
              <uri>model://gate_24/meshes/gate.dae</uri>
            </mesh>
          </geometry>
          <max_contacts>10</max_contacts>
          <surface>
            <contact>
              <ode/>
            </contact>
            <bounce/>
            <friction>
              <torsional>
                <ode/>
              </torsional>
              <ode/>
            </friction>
          </surface>
        </collision>
        <visual name='visual'>
          <cast_shadows>1</cast_shadows>
          <pose>0 0 0 0 -0 0</pose>
          <geometry>
            <mesh>
              <uri>model://gate_24/meshes/gate.dae</uri>
            </mesh>
          </geometry>
        </visual>
        <self_collide>0</self_collide>
        <enable_wind>0</enable_wind>
        <kinematic>0</kinematic>
      </link>
      <pose>8 8 -0.1 0 -0 3.14</pose>
    </model>
    <plugin name='sc_interface' filename='libuuv_sc_ros_interface_plugin.so'/>
    <gui fullscreen='0'>
      <camera name='user_camera'>
        <pose>-21.9709 -0.716209 3.28891 0 1.0658 0.476</pose>
        <view_controller>orbit</view_controller>
        <projection_type>perspective</projection_type>
      </camera>
    </gui>
    <gravity>0 0 -9.8</gravity>
    <magnetic_field>6e-06 2.3e-05 -4.2e-05</magnetic_field>
    <atmosphere type='adiabatic'/>
    <wind/>
    <model name='kf'>
      <link name='kf/base_link'>
        <inertial>
          <pose>0 0 0 0 -0 0</pose>
          <mass>30</mass>
          <inertia>
            <ixx>7</ixx>
            <ixy>0</ixy>
            <ixz>0</ixz>
            <iyy>7</iyy>
            <iyz>0</iyz>
            <izz>4</izz>
          </inertia>
        </inertial>
        <collision name='kf/base_link_collision'>
          <pose>-0.1 0 -0.08 0 -0 0</pose>
          <geometry>
            <box>
              <size>0.986 0.538 0.366</size>
            </box>
          </geometry>
          <surface>
            <contact>
              <ode/>
            </contact>
            <friction>
              <ode/>
              <torsional>
                <ode/>
              </torsional>
            </friction>
            <bounce/>
          </surface>
          <max_contacts>10</max_contacts>
        </collision>
        <visual name='kf/base_link_visual'>
          <pose>-0.1 0 0 0 -0 1.57</pose>
          <geometry>
            <mesh>
              <scale>1 1 1</scale>
              <uri>/home/gleb/catkin_ws/src/TAUV-ROS-Packages/src/packages/tauv_config/kingfisher_sim_description/meshes/KingfisherCoarseNoInsides.obj</uri>
            </mesh>
          </geometry>
        </visual>
        <self_collide>0</self_collide>
        <enable_wind>0</enable_wind>
        <kinematic>0</kinematic>
      </link>
      <joint name='kf/bottom_oakd_joint' type='revolute'>
        <pose relative_to='kf/base_link'>0.254 0 -0.15 1.57 1.57 0</pose>
        <parent>kf/base_link</parent>
        <child>kf/bottom_oakd_link</child>
        <axis>
          <xyz>1 0 0</xyz>
          <limit>
            <lower>0</lower>
            <upper>0</upper>
            <effort>0</effort>
            <velocity>0</velocity>
          </limit>
          <dynamics>
            <spring_reference>0</spring_reference>
            <spring_stiffness>0</spring_stiffness>
          </dynamics>
        </axis>
      </joint>
      <link name='kf/bottom_oakd_link'>
        <pose relative_to='kf/bottom_oakd_joint'>0 0 0 0 -0 0</pose>
        <inertial>
          <pose>0 0 0 0 -0 0</pose>
          <mass>0.0001</mass>
          <inertia>
            <ixx>0</ixx>
            <ixy>0</ixy>
            <ixz>0</ixz>
            <iyy>0</iyy>
            <iyz>0</iyz>
            <izz>0</izz>
          </inertia>
        </inertial>
        <collision name='kf/bottom_oakd_link_collision'>
          <pose>0 0 0 0 -0 0</pose>
          <geometry>
            <box>
              <size>0.0001 0.0001 0.0001</size>
            </box>
          </geometry>
          <surface>
            <contact>
              <ode/>
            </contact>
            <friction>
              <ode/>
              <torsional>
                <ode/>
              </torsional>
            </friction>
            <bounce/>
          </surface>
          <max_contacts>10</max_contacts>
        </collision>
        <visual name='kf/bottom_oakd_link_visual'>
          <pose>0 0 0 0 -0 0</pose>
          <geometry>
            <box>
              <size>0.0001 0.0001 0.0001</size>
            </box>
          </geometry>
        </visual>
        <sensor name='bottom_oakd_stereo' type='multicamera'>
          <camera name='bottom_oakd_left'>
            <pose>0 0.035 0 0 -0 0</pose>
            <horizontal_fov>1.1071</horizontal_fov>
            <image>
              <width>1280</width>
              <height>720</height>
              <format>R8G8B8</format>
            </image>
            <clip>
              <near>0.02</near>
              <far>300</far>
            </clip>
            <noise>
              <type>gaussian</type>
              <mean>0</mean>
              <stddev>0.007</stddev>
            </noise>
            <distortion>
              <k1>0</k1>
              <k2>0</k2>
              <k3>0</k3>
              <p1>0</p1>
              <p2>0</p2>
              <center>0.5 0.5</center>
            </distortion>
          </camera>
          <camera name='bottom_oakd_right'>
            <pose>0 -0.035 0 0 -0 0</pose>
            <horizontal_fov>1.1071</horizontal_fov>
            <image>
              <width>1280</width>
              <height>720</height>
              <format>R8G8B8</format>
            </image>
            <clip>
              <near>0.02</near>
              <far>300</far>
            </clip>
            <noise>
              <type>gaussian</type>
              <mean>0</mean>
              <stddev>0.007</stddev>
            </noise>
            <distortion>
              <k1>0</k1>
              <k2>0</k2>
              <k3>0</k3>
              <p1>0</p1>
              <p2>0</p2>
              <center>0.5 0.5</center>
            </distortion>
          </camera>
          <plugin name='bottom_oakd_stereo_controller' filename='libgazebo_ros_multicamera.so'>
            <alwaysOn>1</alwaysOn>
            <updateRate>10.0</updateRate>
            <cameraName>vehicle/oakd_bottom/stereo</cameraName>
            <imageTopicName>image_raw</imageTopicName>
            <cameraInfoTopicName>camera_info</cameraInfoTopicName>
            <frameName>oakd_bottom</frameName>
            <hackBaseline>0.07</hackBaseline>
            <distortionK1>0</distortionK1>
            <distortionK2>0</distortionK2>
            <distortionK3>0</distortionK3>
            <distortionT1>0</distortionT1>
            <distortionT2>0</distortionT2>
            <robotNamespace>/kf/</robotNamespace>
          </plugin>
        </sensor>
        <sensor name='bottom_oakd_color' type='camera'>
          <camera name='bottom_oakd_color'>
            <horizontal_fov>1.1071</horizontal_fov>
            <image>
              <width>1280</width>
              <height>720</height>
              <format>R8G8B8</format>
            </image>
            <clip>
              <near>0.02</near>
              <far>300</far>
            </clip>
            <noise>
              <type>gaussian</type>
              <mean>0</mean>
              <stddev>0.007</stddev>
            </noise>
            <distortion>
              <k1>0</k1>
              <k2>0</k2>
              <k3>0</k3>
              <p1>0</p1>
              <p2>0</p2>
              <center>0.5 0.5</center>
            </distortion>
          </camera>
          <plugin name='bottom_oakd_color_controller' filename='libgazebo_ros_camera.so'>
            <alwaysOn>1</alwaysOn>
            <updateRate>10.0</updateRate>
            <cameraName>vehicle/oakd_bottom/color</cameraName>
            <imageTopicName>image_raw</imageTopicName>
            <cameraInfoTopicName>camera_info</cameraInfoTopicName>
            <frameName>oakd_bottom</frameName>
            <distortionK1>0</distortionK1>
            <distortionK2>0</distortionK2>
            <distortionK3>0</distortionK3>
            <distortionT1>0</distortionT1>
            <distortionT2>0</distortionT2>
            <robotNamespace>/kf/</robotNamespace>
          </plugin>
          <visualize>1</visualize>
        </sensor>
        <self_collide>0</self_collide>
        <enable_wind>0</enable_wind>
        <kinematic>0</kinematic>
      </link>
      <joint name='kf/front_oakd_joint' type='revolute'>
        <pose relative_to='kf/base_link'>0.5 0 0.0508 0 -0 0</pose>
        <parent>kf/base_link</parent>
        <child>kf/front_oakd_link</child>
        <axis>
          <xyz>1 0 0</xyz>
          <limit>
            <lower>0</lower>
            <upper>0</upper>
            <effort>0</effort>
            <velocity>0</velocity>
          </limit>
          <dynamics>
            <spring_reference>0</spring_reference>
            <spring_stiffness>0</spring_stiffness>
          </dynamics>
        </axis>
      </joint>
      <link name='kf/front_oakd_link'>
        <pose relative_to='kf/front_oakd_joint'>0 0 0 0 -0 0</pose>
        <inertial>
          <pose>0 0 0 0 -0 0</pose>
          <mass>0.0001</mass>
          <inertia>
            <ixx>0</ixx>
            <ixy>0</ixy>
            <ixz>0</ixz>
            <iyy>0</iyy>
            <iyz>0</iyz>
            <izz>0</izz>
          </inertia>
        </inertial>
        <collision name='kf/front_oakd_link_collision'>
          <pose>0 0 0 0 -0 0</pose>
          <geometry>
            <box>
              <size>0.0001 0.0001 0.0001</size>
            </box>
          </geometry>
          <surface>
            <contact>
              <ode/>
            </contact>
            <friction>
              <ode/>
              <torsional>
                <ode/>
              </torsional>
            </friction>
            <bounce/>
          </surface>
          <max_contacts>10</max_contacts>
        </collision>
        <visual name='kf/front_oakd_link_visual'>
          <pose>0 0 0 0 -0 0</pose>
          <geometry>
            <box>
              <size>0.0001 0.0001 0.0001</size>
            </box>
          </geometry>
        </visual>
        <sensor name='front_oakd_stereo' type='multicamera'>
          <camera name='front_oakd_left'>
            <pose>0 0.035 0 0 -0 0</pose>
            <horizontal_fov>1.1071</horizontal_fov>
            <image>
              <width>1280</width>
              <height>720</height>
              <format>R8G8B8</format>
            </image>
            <clip>
              <near>0.02</near>
              <far>300</far>
            </clip>
            <noise>
              <type>gaussian</type>
              <mean>0</mean>
              <stddev>0.007</stddev>
            </noise>
            <distortion>
              <k1>0</k1>
              <k2>0</k2>
              <k3>0</k3>
              <p1>0</p1>
              <p2>0</p2>
              <center>0.5 0.5</center>
            </distortion>
          </camera>
          <camera name='front_oakd_right'>
            <pose>0 -0.035 0 0 -0 0</pose>
            <horizontal_fov>1.1071</horizontal_fov>
            <image>
              <width>1280</width>
              <height>720</height>
              <format>R8G8B8</format>
            </image>
            <clip>
              <near>0.02</near>
              <far>300</far>
            </clip>
            <noise>
              <type>gaussian</type>
              <mean>0</mean>
              <stddev>0.007</stddev>
            </noise>
            <distortion>
              <k1>0</k1>
              <k2>0</k2>
              <k3>0</k3>
              <p1>0</p1>
              <p2>0</p2>
              <center>0.5 0.5</center>
            </distortion>
          </camera>
          <plugin name='front_oakd_stereo_controller' filename='libgazebo_ros_multicamera.so'>
            <alwaysOn>1</alwaysOn>
            <updateRate>10.0</updateRate>
            <cameraName>vehicle/oakd_front/stereo</cameraName>
            <imageTopicName>image_raw</imageTopicName>
            <cameraInfoTopicName>camera_info</cameraInfoTopicName>
            <frameName>oakd_front</frameName>
            <hackBaseline>0.07</hackBaseline>
            <distortionK1>0</distortionK1>
            <distortionK2>0</distortionK2>
            <distortionK3>0</distortionK3>
            <distortionT1>0</distortionT1>
            <distortionT2>0</distortionT2>
            <robotNamespace>/kf/</robotNamespace>
          </plugin>
        </sensor>
        <sensor name='front_oakd_color' type='camera'>
          <camera name='front_oakd_color'>
            <horizontal_fov>1.1071</horizontal_fov>
            <image>
              <width>1280</width>
              <height>720</height>
              <format>R8G8B8</format>
            </image>
            <clip>
              <near>0.02</near>
              <far>300</far>
            </clip>
            <noise>
              <type>gaussian</type>
              <mean>0</mean>
              <stddev>0.007</stddev>
            </noise>
            <distortion>
              <k1>0</k1>
              <k2>0</k2>
              <k3>0</k3>
              <p1>0</p1>
              <p2>0</p2>
              <center>0.5 0.5</center>
              <distortionModel>plumb_bob</distortionModel>
            </distortion>
          </camera>
          <plugin name='front_oakd_color_controller' filename='libgazebo_ros_camera.so'>
            <alwaysOn>1</alwaysOn>
            <updateRate>10.0</updateRate>
            <cameraName>vehicle/oakd_front/color</cameraName>
            <imageTopicName>image_raw</imageTopicName>
            <cameraInfoTopicName>camera_info</cameraInfoTopicName>
            <frameName>oakd_front</frameName>
            <distortionK1>0</distortionK1>
            <distortionK2>0</distortionK2>
            <distortionK3>0</distortionK3>
            <distortionT1>0</distortionT1>
            <distortionT2>0</distortionT2>
            <robotNamespace>/kf/</robotNamespace>
          </plugin>
          <visualize>1</visualize>
        </sensor>
        <self_collide>0</self_collide>
        <enable_wind>0</enable_wind>
        <kinematic>0</kinematic>
      </link>
      <joint name='kf/navigation_state_sensor_joint' type='revolute'>
        <pose relative_to='kf/base_link'>0 0 0 0 -0 0</pose>
        <parent>kf/base_link</parent>
        <child>kf/navigation_state_sensor</child>
        <axis>
          <xyz>1 0 0</xyz>
          <limit>
            <lower>0</lower>
            <upper>0</upper>
            <effort>0</effort>
            <velocity>0</velocity>
          </limit>
          <dynamics>
            <spring_reference>0</spring_reference>
            <spring_stiffness>0</spring_stiffness>
          </dynamics>
        </axis>
      </joint>
      <link name='kf/navigation_state_sensor'>
        <pose relative_to='kf/navigation_state_sensor_joint'>0 0 0 0 -0 0</pose>
        <inertial>
          <pose>0 0 0 0 -0 0</pose>
          <mass>0.0001</mass>
          <inertia>
            <ixx>0</ixx>
            <ixy>0</ixy>
            <ixz>0</ixz>
            <iyy>0</iyy>
            <iyz>0</iyz>
            <izz>0</izz>
          </inertia>
        </inertial>
        <collision name='kf/navigation_state_sensor_collision'>
          <pose>0 0 0 0 -0 0</pose>
          <geometry>
            <box>
              <size>0.0001 0.0001 0.0001</size>
            </box>
          </geometry>
          <surface>
            <contact>
              <ode/>
            </contact>
            <friction>
              <ode/>
              <torsional>
                <ode/>
              </torsional>
            </friction>
            <bounce/>
          </surface>
          <max_contacts>10</max_contacts>
        </collision>
        <visual name='kf/navigation_state_sensor_visual'>
          <pose>0 0 0 0 -0 0</pose>
          <geometry>
            <box>
              <size>0.0001 0.0001 0.0001</size>
            </box>
          </geometry>
        </visual>
        <self_collide>0</self_collide>
        <enable_wind>0</enable_wind>
        <kinematic>0</kinematic>
      </link>
      <joint name='kf/thruster_0_joint' type='revolute'>
        <pose relative_to='kf/base_link'>0.43852 -0.22093 0 1.5708 0 0.785398</pose>
        <parent>kf/base_link</parent>
        <child>kf/thruster_0</child>
        <axis>
          <xyz>1 0 0</xyz>
          <limit>
            <lower>-1e+16</lower>
            <upper>1e+16</upper>
          </limit>
          <dynamics>
            <spring_reference>0</spring_reference>
            <spring_stiffness>0</spring_stiffness>
          </dynamics>
        </axis>
      </joint>
      <link name='kf/thruster_0'>
        <pose relative_to='kf/thruster_0_joint'>0 0 0 0 -0 0</pose>
        <inertial>
          <pose>0 0 0 0 -0 0</pose>
          <mass>0.0001</mass>
          <inertia>
            <ixx>0</ixx>
            <ixy>0</ixy>
            <ixz>0</ixz>
            <iyy>0</iyy>
            <iyz>0</iyz>
            <izz>0</izz>
          </inertia>
        </inertial>
        <collision name='kf/thruster_0_collision'>
          <pose>0 0 0 0 -0 0</pose>
          <geometry>
            <box>
              <size>0.0001 0.0001 0.0001</size>
            </box>
          </geometry>
          <surface>
            <contact>
              <ode/>
            </contact>
            <friction>
              <ode/>
              <torsional>
                <ode/>
              </torsional>
            </friction>
            <bounce/>
          </surface>
          <max_contacts>10</max_contacts>
        </collision>
        <visual name='kf/thruster_0_visual'>
          <pose>0 0 0 0 -0 0</pose>
          <geometry>
            <box>
              <size>0.0001 0.0001 0.0001</size>
            </box>
          </geometry>
        </visual>
        <self_collide>0</self_collide>
        <enable_wind>0</enable_wind>
        <kinematic>0</kinematic>
      </link>
      <joint name='kf/thruster_1_joint' type='revolute'>
        <pose relative_to='kf/base_link'>0.43852 0.22093 0 1.5708 -0 -0.785398</pose>
        <parent>kf/base_link</parent>
        <child>kf/thruster_1</child>
        <axis>
          <xyz>1 0 0</xyz>
          <limit>
            <lower>-1e+16</lower>
            <upper>1e+16</upper>
          </limit>
          <dynamics>
            <spring_reference>0</spring_reference>
            <spring_stiffness>0</spring_stiffness>
          </dynamics>
        </axis>
      </joint>
      <link name='kf/thruster_1'>
        <pose relative_to='kf/thruster_1_joint'>0 0 0 0 -0 0</pose>
        <inertial>
          <pose>0 0 0 0 -0 0</pose>
          <mass>0.0001</mass>
          <inertia>
            <ixx>0</ixx>
            <ixy>0</ixy>
            <ixz>0</ixz>
            <iyy>0</iyy>
            <iyz>0</iyz>
            <izz>0</izz>
          </inertia>
        </inertial>
        <collision name='kf/thruster_1_collision'>
          <pose>0 0 0 0 -0 0</pose>
          <geometry>
            <box>
              <size>0.0001 0.0001 0.0001</size>
            </box>
          </geometry>
          <surface>
            <contact>
              <ode/>
            </contact>
            <friction>
              <ode/>
              <torsional>
                <ode/>
              </torsional>
            </friction>
            <bounce/>
          </surface>
          <max_contacts>10</max_contacts>
        </collision>
        <visual name='kf/thruster_1_visual'>
          <pose>0 0 0 0 -0 0</pose>
          <geometry>
            <box>
              <size>0.0001 0.0001 0.0001</size>
            </box>
          </geometry>
        </visual>
        <self_collide>0</self_collide>
        <enable_wind>0</enable_wind>
        <kinematic>0</kinematic>
      </link>
      <joint name='kf/thruster_2_joint' type='revolute'>
        <pose relative_to='kf/base_link'>-0.43852 -0.22093 0 -1.5708 -0 2.35619</pose>
        <parent>kf/base_link</parent>
        <child>kf/thruster_2</child>
        <axis>
          <xyz>1 0 0</xyz>
          <limit>
            <lower>-1e+16</lower>
            <upper>1e+16</upper>
          </limit>
          <dynamics>
            <spring_reference>0</spring_reference>
            <spring_stiffness>0</spring_stiffness>
          </dynamics>
        </axis>
      </joint>
      <link name='kf/thruster_2'>
        <pose relative_to='kf/thruster_2_joint'>0 0 0 0 -0 0</pose>
        <inertial>
          <pose>0 0 0 0 -0 0</pose>
          <mass>0.0001</mass>
          <inertia>
            <ixx>0</ixx>
            <ixy>0</ixy>
            <ixz>0</ixz>
            <iyy>0</iyy>
            <iyz>0</iyz>
            <izz>0</izz>
          </inertia>
        </inertial>
        <collision name='kf/thruster_2_collision'>
          <pose>0 0 0 0 -0 0</pose>
          <geometry>
            <box>
              <size>0.0001 0.0001 0.0001</size>
            </box>
          </geometry>
          <surface>
            <contact>
              <ode/>
            </contact>
            <friction>
              <ode/>
              <torsional>
                <ode/>
              </torsional>
            </friction>
            <bounce/>
          </surface>
          <max_contacts>10</max_contacts>
        </collision>
        <visual name='kf/thruster_2_visual'>
          <pose>0 0 0 0 -0 0</pose>
          <geometry>
            <box>
              <size>0.0001 0.0001 0.0001</size>
            </box>
          </geometry>
        </visual>
        <self_collide>0</self_collide>
        <enable_wind>0</enable_wind>
        <kinematic>0</kinematic>
      </link>
      <joint name='kf/thruster_3_joint' type='revolute'>
        <pose relative_to='kf/base_link'>-0.43852 0.22093 0 -1.5708 -0 -2.35619</pose>
        <parent>kf/base_link</parent>
        <child>kf/thruster_3</child>
        <axis>
          <xyz>1 0 0</xyz>
          <limit>
            <lower>-1e+16</lower>
            <upper>1e+16</upper>
          </limit>
          <dynamics>
            <spring_reference>0</spring_reference>
            <spring_stiffness>0</spring_stiffness>
          </dynamics>
        </axis>
      </joint>
      <link name='kf/thruster_3'>
        <pose relative_to='kf/thruster_3_joint'>0 0 0 0 -0 0</pose>
        <inertial>
          <pose>0 0 0 0 -0 0</pose>
          <mass>0.0001</mass>
          <inertia>
            <ixx>0</ixx>
            <ixy>0</ixy>
            <ixz>0</ixz>
            <iyy>0</iyy>
            <iyz>0</iyz>
            <izz>0</izz>
          </inertia>
        </inertial>
        <collision name='kf/thruster_3_collision'>
          <pose>0 0 0 0 -0 0</pose>
          <geometry>
            <box>
              <size>0.0001 0.0001 0.0001</size>
            </box>
          </geometry>
          <surface>
            <contact>
              <ode/>
            </contact>
            <friction>
              <ode/>
              <torsional>
                <ode/>
              </torsional>
            </friction>
            <bounce/>
          </surface>
          <max_contacts>10</max_contacts>
        </collision>
        <visual name='kf/thruster_3_visual'>
          <pose>0 0 0 0 -0 0</pose>
          <geometry>
            <box>
              <size>0.0001 0.0001 0.0001</size>
            </box>
          </geometry>
        </visual>
        <self_collide>0</self_collide>
        <enable_wind>0</enable_wind>
        <kinematic>0</kinematic>
      </link>
      <joint name='kf/thruster_4_joint' type='revolute'>
        <pose relative_to='kf/base_link'>0.23876 -0.213083 -0.01115 -1.57079 1.57079 3.14159</pose>
        <parent>kf/base_link</parent>
        <child>kf/thruster_4</child>
        <axis>
          <xyz>1 0 0</xyz>
          <limit>
            <lower>-1e+16</lower>
            <upper>1e+16</upper>
          </limit>
          <dynamics>
            <spring_reference>0</spring_reference>
            <spring_stiffness>0</spring_stiffness>
          </dynamics>
        </axis>
      </joint>
      <link name='kf/thruster_4'>
        <pose relative_to='kf/thruster_4_joint'>0 0 0 0 -0 0</pose>
        <inertial>
          <pose>0 0 0 0 -0 0</pose>
          <mass>0.0001</mass>
          <inertia>
            <ixx>0</ixx>
            <ixy>0</ixy>
            <ixz>0</ixz>
            <iyy>0</iyy>
            <iyz>0</iyz>
            <izz>0</izz>
          </inertia>
        </inertial>
        <collision name='kf/thruster_4_collision'>
          <pose>0 0 0 0 -0 0</pose>
          <geometry>
            <box>
              <size>0.0001 0.0001 0.0001</size>
            </box>
          </geometry>
          <surface>
            <contact>
              <ode/>
            </contact>
            <friction>
              <ode/>
              <torsional>
                <ode/>
              </torsional>
            </friction>
            <bounce/>
          </surface>
          <max_contacts>10</max_contacts>
        </collision>
        <visual name='kf/thruster_4_visual'>
          <pose>0 0 0 0 -0 0</pose>
          <geometry>
            <box>
              <size>0.0001 0.0001 0.0001</size>
            </box>
          </geometry>
        </visual>
        <self_collide>0</self_collide>
        <enable_wind>0</enable_wind>
        <kinematic>0</kinematic>
      </link>
      <joint name='kf/thruster_5_joint' type='revolute'>
        <pose relative_to='kf/base_link'>0.23876 0.21308 -0.01115 -1.57079 1.57079 3.14159</pose>
        <parent>kf/base_link</parent>
        <child>kf/thruster_5</child>
        <axis>
          <xyz>1 0 0</xyz>
          <limit>
            <lower>-1e+16</lower>
            <upper>1e+16</upper>
          </limit>
          <dynamics>
            <spring_reference>0</spring_reference>
            <spring_stiffness>0</spring_stiffness>
          </dynamics>
        </axis>
      </joint>
      <link name='kf/thruster_5'>
        <pose relative_to='kf/thruster_5_joint'>0 0 0 0 -0 0</pose>
        <inertial>
          <pose>0 0 0 0 -0 0</pose>
          <mass>0.0001</mass>
          <inertia>
            <ixx>0</ixx>
            <ixy>0</ixy>
            <ixz>0</ixz>
            <iyy>0</iyy>
            <iyz>0</iyz>
            <izz>0</izz>
          </inertia>
        </inertial>
        <collision name='kf/thruster_5_collision'>
          <pose>0 0 0 0 -0 0</pose>
          <geometry>
            <box>
              <size>0.0001 0.0001 0.0001</size>
            </box>
          </geometry>
          <surface>
            <contact>
              <ode/>
            </contact>
            <friction>
              <ode/>
              <torsional>
                <ode/>
              </torsional>
            </friction>
            <bounce/>
          </surface>
          <max_contacts>10</max_contacts>
        </collision>
        <visual name='kf/thruster_5_visual'>
          <pose>0 0 0 0 -0 0</pose>
          <geometry>
            <box>
              <size>0.0001 0.0001 0.0001</size>
            </box>
          </geometry>
        </visual>
        <self_collide>0</self_collide>
        <enable_wind>0</enable_wind>
        <kinematic>0</kinematic>
      </link>
      <joint name='kf/thruster_6_joint' type='revolute'>
        <pose relative_to='kf/base_link'>-0.23876 -0.213083 -0.01115 -1.57079 1.57079 3.14159</pose>
        <parent>kf/base_link</parent>
        <child>kf/thruster_6</child>
        <axis>
          <xyz>1 0 0</xyz>
          <limit>
            <lower>-1e+16</lower>
            <upper>1e+16</upper>
          </limit>
          <dynamics>
            <spring_reference>0</spring_reference>
            <spring_stiffness>0</spring_stiffness>
          </dynamics>
        </axis>
      </joint>
      <link name='kf/thruster_6'>
        <pose relative_to='kf/thruster_6_joint'>0 0 0 0 -0 0</pose>
        <inertial>
          <pose>0 0 0 0 -0 0</pose>
          <mass>0.0001</mass>
          <inertia>
            <ixx>0</ixx>
            <ixy>0</ixy>
            <ixz>0</ixz>
            <iyy>0</iyy>
            <iyz>0</iyz>
            <izz>0</izz>
          </inertia>
        </inertial>
        <collision name='kf/thruster_6_collision'>
          <pose>0 0 0 0 -0 0</pose>
          <geometry>
            <box>
              <size>0.0001 0.0001 0.0001</size>
            </box>
          </geometry>
          <surface>
            <contact>
              <ode/>
            </contact>
            <friction>
              <ode/>
              <torsional>
                <ode/>
              </torsional>
            </friction>
            <bounce/>
          </surface>
          <max_contacts>10</max_contacts>
        </collision>
        <visual name='kf/thruster_6_visual'>
          <pose>0 0 0 0 -0 0</pose>
          <geometry>
            <box>
              <size>0.0001 0.0001 0.0001</size>
            </box>
          </geometry>
        </visual>
        <self_collide>0</self_collide>
        <enable_wind>0</enable_wind>
        <kinematic>0</kinematic>
      </link>
      <joint name='kf/thruster_7_joint' type='revolute'>
        <pose relative_to='kf/base_link'>-0.23876 0.21308 -0.01115 -1.57079 1.57079 3.14159</pose>
        <parent>kf/base_link</parent>
        <child>kf/thruster_7</child>
        <axis>
          <xyz>1 0 0</xyz>
          <limit>
            <lower>-1e+16</lower>
            <upper>1e+16</upper>
          </limit>
          <dynamics>
            <spring_reference>0</spring_reference>
            <spring_stiffness>0</spring_stiffness>
          </dynamics>
        </axis>
      </joint>
      <link name='kf/thruster_7'>
        <pose relative_to='kf/thruster_7_joint'>0 0 0 0 -0 0</pose>
        <inertial>
          <pose>0 0 0 0 -0 0</pose>
          <mass>0.0001</mass>
          <inertia>
            <ixx>0</ixx>
            <ixy>0</ixy>
            <ixz>0</ixz>
            <iyy>0</iyy>
            <iyz>0</iyz>
            <izz>0</izz>
          </inertia>
        </inertial>
        <collision name='kf/thruster_7_collision'>
          <pose>0 0 0 0 -0 0</pose>
          <geometry>
            <box>
              <size>0.0001 0.0001 0.0001</size>
            </box>
          </geometry>
          <surface>
            <contact>
              <ode/>
            </contact>
            <friction>
              <ode/>
              <torsional>
                <ode/>
              </torsional>
            </friction>
            <bounce/>
          </surface>
          <max_contacts>10</max_contacts>
        </collision>
        <visual name='kf/thruster_7_visual'>
          <pose>0 0 0 0 -0 0</pose>
          <geometry>
            <box>
              <size>0.0001 0.0001 0.0001</size>
            </box>
          </geometry>
        </visual>
        <self_collide>0</self_collide>
        <enable_wind>0</enable_wind>
        <kinematic>0</kinematic>
      </link>
      <plugin name='kf_uuv_plugin' filename='libuuv_underwater_object_ros_plugin.so'>
        <fluid_density>1028.0</fluid_density>
        <flow_velocity_topic>hydrodynamics/current_velocity</flow_velocity_topic>
        <debug>1</debug>
        <link name='kf/base_link'>
          <neutrally_buoyant>0</neutrally_buoyant>
          <volume>0.03</volume>
          <box>
            <length>0.986</length>
            <width>0.538</width>
            <height>0.366</height>
          </box>
          <center_of_buoyancy>0.02 0 0.13</center_of_buoyancy>
          <hydrodynamic_model>
            <type>fossen</type>
            <added_mass>0 0 0 0 0 0 0 0 0 0 0 0 0 0 0 0 0 0 0 0 0 0 0 0 0 0 0 0 0 0 0 0 0 0 0 0</added_mass>
            <linear_damping>-62.3844 -83.1339 -44.2445 -7.69374 -5.65474 -3.10541</linear_damping>
            <quadratic_damping>0 0 0 0 0 0</quadratic_damping>
          </hydrodynamic_model>
        </link>
        <robotNamespace>/kf/</robotNamespace>
      </plugin>
      <plugin name='kf_thruster_0' filename='libtauv_thruster_plugin.so'>
        <linkName>kf/thruster_0</linkName>
        <timeConstant>0.001</timeConstant>
        <publishRate>50</publishRate>
        <nodeName>kf_thruster_0_plugin</nodeName>
        <targetThrustTopic>/kf/vehicle/thrusters/0/target_thrust</targetThrustTopic>
        <thrustTopic>/kf/vehicle/thrusters/0/thrust</thrustTopic>
        <maxThrust>50</maxThrust>
        <minThrust>-40</minThrust>
        <robotNamespace>/kf/</robotNamespace>
      </plugin>
      <plugin name='kf_thruster_1' filename='libtauv_thruster_plugin.so'>
        <linkName>kf/thruster_1</linkName>
        <timeConstant>0.001</timeConstant>
        <publishRate>50</publishRate>
        <nodeName>kf_thruster_1_plugin</nodeName>
        <targetThrustTopic>/kf/vehicle/thrusters/1/target_thrust</targetThrustTopic>
        <thrustTopic>/kf/vehicle/thrusters/1/thrust</thrustTopic>
        <maxThrust>50</maxThrust>
        <minThrust>-40</minThrust>
        <robotNamespace>/kf/</robotNamespace>
      </plugin>
      <plugin name='kf_thruster_2' filename='libtauv_thruster_plugin.so'>
        <linkName>kf/thruster_2</linkName>
        <timeConstant>0.001</timeConstant>
        <publishRate>50</publishRate>
        <nodeName>kf_thruster_2_plugin</nodeName>
        <targetThrustTopic>/kf/vehicle/thrusters/2/target_thrust</targetThrustTopic>
        <thrustTopic>/kf/vehicle/thrusters/2/thrust</thrustTopic>
        <maxThrust>50</maxThrust>
        <minThrust>-40</minThrust>
        <robotNamespace>/kf/</robotNamespace>
      </plugin>
      <plugin name='kf_thruster_3' filename='libtauv_thruster_plugin.so'>
        <linkName>kf/thruster_3</linkName>
        <timeConstant>0.001</timeConstant>
        <publishRate>50</publishRate>
        <nodeName>kf_thruster_3_plugin</nodeName>
        <targetThrustTopic>/kf/vehicle/thrusters/3/target_thrust</targetThrustTopic>
        <thrustTopic>/kf/vehicle/thrusters/3/thrust</thrustTopic>
        <maxThrust>50</maxThrust>
        <minThrust>-40</minThrust>
        <robotNamespace>/kf/</robotNamespace>
      </plugin>
      <plugin name='kf_thruster_4' filename='libtauv_thruster_plugin.so'>
        <linkName>kf/thruster_4</linkName>
        <timeConstant>0.001</timeConstant>
        <publishRate>50</publishRate>
        <nodeName>kf_thruster_4_plugin</nodeName>
        <targetThrustTopic>/kf/vehicle/thrusters/4/target_thrust</targetThrustTopic>
        <thrustTopic>/kf/vehicle/thrusters/4/thrust</thrustTopic>
        <maxThrust>50</maxThrust>
        <minThrust>-40</minThrust>
        <robotNamespace>/kf/</robotNamespace>
      </plugin>
      <plugin name='kf_thruster_5' filename='libtauv_thruster_plugin.so'>
        <linkName>kf/thruster_5</linkName>
        <timeConstant>0.001</timeConstant>
        <publishRate>50</publishRate>
        <nodeName>kf_thruster_5_plugin</nodeName>
        <targetThrustTopic>/kf/vehicle/thrusters/5/target_thrust</targetThrustTopic>
        <thrustTopic>/kf/vehicle/thrusters/5/thrust</thrustTopic>
        <maxThrust>50</maxThrust>
        <minThrust>-40</minThrust>
        <robotNamespace>/kf/</robotNamespace>
      </plugin>
      <plugin name='kf_thruster_6' filename='libtauv_thruster_plugin.so'>
        <linkName>kf/thruster_6</linkName>
        <timeConstant>0.001</timeConstant>
        <publishRate>50</publishRate>
        <nodeName>kf_thruster_6_plugin</nodeName>
        <targetThrustTopic>/kf/vehicle/thrusters/6/target_thrust</targetThrustTopic>
        <thrustTopic>/kf/vehicle/thrusters/6/thrust</thrustTopic>
        <maxThrust>50</maxThrust>
        <minThrust>-40</minThrust>
        <robotNamespace>/kf/</robotNamespace>
      </plugin>
      <plugin name='kf_thruster_7' filename='libtauv_thruster_plugin.so'>
        <linkName>kf/thruster_7</linkName>
        <timeConstant>0.001</timeConstant>
        <publishRate>50</publishRate>
        <nodeName>kf_thruster_7_plugin</nodeName>
        <targetThrustTopic>/kf/vehicle/thrusters/7/target_thrust</targetThrustTopic>
        <thrustTopic>/kf/vehicle/thrusters/7/thrust</thrustTopic>
        <maxThrust>50</maxThrust>
        <minThrust>-40</minThrust>
        <robotNamespace>/kf/</robotNamespace>
      </plugin>
      <static>0</static>
      <plugin name='kf_navigation_state_sensor' filename='libtauv_navigation_state_plugin.so'>
        <linkName>kf/navigation_state_sensor</linkName>
        <publishRate>50</publishRate>
        <nodeName>kf_navigation_state_plugin</nodeName>
        <navigationStateTopic>/kf/gnc/navigation_state</navigationStateTopic>
        <odomTopic>/kf/gnc/odom</odomTopic>
        <tfNamespace>kf</tfNamespace>
        <robotNamespace>/kf/</robotNamespace>
      </plugin>
      <pose>5 5 -2 0 -0 1.57</pose>
    </model>
    <state world_name='umd'>
      <sim_time>1483 536000000</sim_time>
      <real_time>1422 608593113</real_time>
      <wall_time>1722839299 533955555</wall_time>
      <iterations>709255</iterations>
      <model name='gate'>
        <pose>-19.2385 -3.84596 -0.1 0.013544 0.000478 1.56481</pose>
        <scale>1 1 1</scale>
        <link name='base_link'>
          <pose>-19.2385 -3.84596 -0.1 0.013544 0.000478 1.56481</pose>
          <velocity>0 0 0 0 -0 0</velocity>
          <acceleration>0 0 0 0 -0 0</acceleration>
          <wrench>0 0 0 0 -0 0</wrench>
        </link>
      </model>
      <model name='kf'>
        <pose>4.99993 4.9178 -0.173044 0 -0.15263 1.57</pose>
        <scale>1 1 1</scale>
        <link name='kf/base_link'>
          <pose>4.99993 4.9178 -0.173044 0 -0.15263 1.57</pose>
          <velocity>-0 -0 0 0 -0 0</velocity>
          <acceleration>-0 -0 0 0 -0 0</acceleration>
          <wrench>-0 -0 0 0 -0 0</wrench>
        </link>
        <link name='kf/bottom_oakd_link'>
          <pose>5.00015 5.19165 -0.282683 1.57 1.41737 1.57</pose>
          <velocity>0 -0 -0 0 -0 0</velocity>
          <acceleration>0 -0 0 0 -0 0</acceleration>
          <wrench>0 -0 0 0 -0 0</wrench>
        </link>
        <link name='kf/front_oakd_link'>
          <pose>5.00032 5.40426 -0.046816 0 -0.15263 1.57</pose>
          <velocity>0 -0 0 0 -0 0</velocity>
          <acceleration>-0 -0 0 0 -0 0</acceleration>
          <wrench>-0 -0 0 0 -0 0</wrench>
        </link>
        <link name='kf/navigation_state_sensor'>
          <pose>4.99993 4.9178 -0.173044 0 -0.15263 1.57</pose>
          <velocity>-0 -0 0 0 -0 0</velocity>
          <acceleration>-0 -0 0 0 -0 0</acceleration>
          <wrench>-0 -0 0 0 -0 0</wrench>
        </link>
        <link name='kf/thruster_0'>
          <pose>5.22121 5.35105 -0.106372 1.57038 -0.107715 2.36124</pose>
          <velocity>0 -0 -0 0 -0 0</velocity>
          <acceleration>-0 -0 0 0 -0 0</acceleration>
          <wrench>-0 -0 0 0 -0 0</wrench>
        </link>
        <link name='kf/thruster_1'>
          <pose>4.77935 5.3514 -0.106372 1.57122 -0.107715 0.778755</pose>
          <velocity>0 -0 0 0 -0 0</velocity>
          <acceleration>0 0 -0 0 -0 0</acceleration>
          <wrench>0 0 -0 0 -0 0</wrench>
        </link>
        <link name='kf/thruster_2'>
          <pose>5.22051 4.4842 -0.239716 -1.57122 0.107715 -2.36284</pose>
          <velocity>-0 -0 -0 0 -0 0</velocity>
          <acceleration>-0 -0 0 0 -0 0</acceleration>
          <wrench>-0 -0 0 0 -0 0</wrench>
        </link>
        <link name='kf/thruster_3'>
          <pose>4.77865 4.48455 -0.239716 -1.57038 0.107715 -0.780343</pose>
          <velocity>-0 0 0 -0 -0 -0</velocity>
          <acceleration>0 0 -0 0 -0 0</acceleration>
          <wrench>0 0 -0 0 -0 0</wrench>
        </link>
        <link name='kf/thruster_4'>
          <pose>5.2132 5.15531 -0.147764 1.5708 1.41817 1.57</pose>
          <velocity>-0 -0 -0 0 -0 0</velocity>
          <acceleration>0 -0 0 0 -0 0</acceleration>
          <wrench>0 -0 0 0 -0 0</wrench>
        </link>
        <link name='kf/thruster_5'>
          <pose>4.78704 5.15565 -0.147764 1.5708 1.41817 1.57</pose>
          <velocity>-0 -0 -0 0 -0 0</velocity>
          <acceleration>0 0 -0 0 -0 0</acceleration>
          <wrench>0 0 -0 0 -0 0</wrench>
        </link>
        <link name='kf/thruster_6'>
          <pose>5.21283 4.68334 -0.220365 1.5708 1.41817 1.57</pose>
          <velocity>0 -0 0 0 -0 0</velocity>
          <acceleration>0 -0 0 0 -0 0</acceleration>
          <wrench>0 -0 0 0 -0 0</wrench>
        </link>
        <link name='kf/thruster_7'>
          <pose>4.78666 4.68368 -0.220365 1.5708 1.41817 1.57</pose>
          <velocity>0 0 0 0 -0 0</velocity>
          <acceleration>0 0 -0 0 -0 0</acceleration>
          <wrench>0 0 -0 0 -0 0</wrench>
        </link>
      </model>
      <model name='path_marker'>
        <pose>-20.3379 1.3791 0 0 -0 0</pose>
        <scale>1 1 1</scale>
        <link name='base_link'>
          <pose>-20.3379 1.3791 0 0 -0 0</pose>
          <velocity>0 0 0 0 -0 0</velocity>
          <acceleration>0 0 0 0 -0 0</acceleration>
          <wrench>0 0 0 0 -0 0</wrench>
        </link>
      </model>
      <model name='umd'>
        <pose>0 0 0 0 -0 0</pose>
        <scale>1 1 1</scale>
        <link name='base_link'>
          <pose>0 0 0 0 -0 0</pose>
          <velocity>0 0 0 0 -0 0</velocity>
          <acceleration>0 0 0 0 -0 0</acceleration>
          <wrench>0 0 0 0 -0 0</wrench>
        </link>
      </model>
      <model name='water'>
        <pose>0 0 0 0 -0 0</pose>
        <scale>1 1 1</scale>
        <link name='water_link'>
          <pose>0 0 0 0 -0 0</pose>
          <velocity>0 0 0 0 -0 0</velocity>
          <acceleration>0 0 0 0 -0 0</acceleration>
          <wrench>0 0 0 0 -0 0</wrench>
        </link>
      </model>
      <light name='sun'>
        <pose>-50 -50 150 0 -0 0</pose>
      </light>
      <light name='sun_diffuse'>
        <pose>-50 0 -150 0 -0 0</pose>
      </light>
    </state>
    <model name='path_marker'>
      <static>1</static>
      <link name='base_link'>
        <collision name='collision'>
          <pose>0 0 0 0 -0 0</pose>
          <geometry>
            <mesh>
              <uri>model://bin_24/meshes/bin_24.dae</uri>
            </mesh>
          </geometry>
          <max_contacts>10</max_contacts>
          <surface>
            <contact>
              <ode/>
            </contact>
            <bounce/>
            <friction>
              <torsional>
                <ode/>
              </torsional>
              <ode/>
            </friction>
          </surface>
        </collision>
        <visual name='visual'>
          <cast_shadows>1</cast_shadows>
          <pose>0 0 0 0 -0 0</pose>
          <geometry>
            <mesh>
              <uri>model://bin_24/meshes/bin_24.dae</uri>
            </mesh>
          </geometry>
        </visual>
        <self_collide>0</self_collide>
        <enable_wind>0</enable_wind>
        <kinematic>0</kinematic>
      </link>
      <pose>-19.5269 1.3791 0 0 -0 0</pose>
      <enable_wind>0</enable_wind>
    </model>
  </world>
</sdf>
